Workbook
Name ZOTERO_BREF_Vhn5ZmXUdLgL: HP!$CR$4

Sheet Beams
A1: Beam Calculator
K2: Results | N2: Axial | O2: Bending Stress | Q2: Shear Stress | S2: Torsional Stress | U2: Combined Stress | X2: MS
N3: {=IF(B24="W",(W!CG1:CQ530),IF(B24="M",(M!CG1:CQ19),IF(B24="S",(S!CG1:CQ530),IF(B24="HP",(HP!CG1:CQ530),IF(B24="C",('C'!CG1:CQ530),IF(B24="MC",(MC!CG1:CQ530),IF(B24="L",(L!CG1:CQ530),IF(B24="WT",(WT!CG1:CQ530),IF(B24="MT",(MT!CG1:CQ530),IF(B24="HSS",(HSS!CG1:CQ530),IF(B24="CHS",(CHS!CG1:CQ530),IF(B24="PIPE",(PIPE!CG1:CQ530)))))))))))))} -> Axial | O3: Bending Stress | P3: 0 | Q3: Shear Stress | R3: 0 | S3: Torsional Stress | T3: 0 | U3: Combined Stress | V3: 0 | W3: 0 | X3: Min MS
A4: Last Update: | B4: 45966 | N4: Stress | O4: X-axis | P4: Y-axis | Q4: X-axis | R4: Y-axis | S4: Flange | T4: Web | U4: Flange | V4: Web | W4: 0 | X4: 0
K5: {=IF(B24="W",(W!A3:C530),IF(B24="M",M!A3:C530,IF(B24="S",S!A3:C530,IF(B24="HP",HP!A3:C530,IF(B24="C",'C'!A3:C530,IF(B24="MC",MC!A3:C530,IF(B24="L",L!A3:C530,IF(B24="WT",WT!A3:C530,IF(B24="MT",MT!A3:C530,IF(B24="HSS",HSS!A3:C530,IF(B24="CHS",CHS!A3:C530,IF(B24="PIPE",PIPE!A3:C530))))))))))))} -> Type | L5: EDI_Std_Nomenclature | M5: AISC_Manual_Label | N5: 0 | O5: 0 | P5: 0 | Q5: 0 | R5: 0 | S5: 0 | T5: 0 | U5: 0 | V5: 0 | W5: 0 | X5: 0
A6: Inputs | K6: W | L6: W44X408 | M6: W44X408 | N6: 93.666667 | O6: 6.4971098 | P6: 59.470899 | Q6: 586.12661 | R6: 236.63659 | S6: 182.0209 | T6: 102.33433 | U6: 1074.9471 | V6: 474.22653 | W6: 0 | X6: 17.605567
B7: X | C7: Y | F7: Beam Options: | K7: W | L7: W44X368 | M7: W44X368 | N7: 104.07407 | O7: 7.2051282 | P7: 66.508876 | Q7: 657.19872 | R7: 263.25806 | S7: 221.428 | T7: 123.64 | U7: 1214.2612 | V7: 534.21303 | W7: 0 | X7: 15.470921
A8: Applied Shear | B8: 11240 | C8: 11240 | D8: lbs | F8: W | K8: W | L8: W44X335 | M8: W44X335 | N8: 114.11168 | O8: 7.9716312 | P8: 74.933333 | Q8: 735.57439 | R8: 282.46496 | S8: 266.32932 | T8: 154.9826 | U8: 1369.2401 | V8: 591.80548 | W8: 0 | X8: 13.606642
A9: Applied Moment | B9: 11240 | C9: 11240 | D9: in-lbs | F9: M | K9: W | L9: W44X290 | M9: W44X290 | N9: 131.61593 | O9: 9.0645161 | P9: 85.151515 | Q9: 848.19864 | R9: 337.36844 | S9: 348.90373 | T9: 191.01375 | U9: 1604.5324 | V9: 708.45694 | W9: 0 | X9: 11.46469
F10: S | K10: W | L10: W44X262 | M10: W44X262 | N10: 145.59585 | O10: 10.126126 | P10: 96.068376 | Q10: 956.20527 | R10: 374.30029 | S10: 427.90349 | T10: 236.55228 | U10: 1831.8537 | V10: 807.19975 | W10: 0 | X10: 9.9179022
A11: Applied Axial | B11: 11240 | C11: lbs | F11: HP | K11: W | L11: W44X230 | M11: W44X230 | N11: 165.78171 | O11: 11.575695 | P11: 111.28713 | Q11: 1111.1294 | R11: 416.32449 | S11: 550.71486 | T11: 320.49799 | U11: 2167.2568 | V11: 954.69932 | W11: 0 | X11: 8.2282558
A12: Applied Torsion | B12: 11240 | C12: in-lbs | F12: C | K12: W | L12: W40X655 | M12: W40X655 | N12: 58.238342 | O12: 4.3397683 | P12: 33.058824 | Q12: 292.6219 | R12: 154.50519 | S12: 67.554499 | T12: 37.593888 | U12: 528.88561 | V12: 291.55083 | W12: 0 | X12: 36.815361
F13: MC | K13: W | L13: W40X593 | M13: W40X593 | N13: 64.597701 | O13: 4.8034188 | P13: 37.218543 | Q13: 330.72633 | R13: 170.68813 | S13: 81.584719 | T13: 45.212584 | U13: 599.56289 | V13: 323.88824 | W13: 0 | X13: 32.357635
F14: L | K14: W | L14: W40X503 | M14: W40X503 | N14: 75.945946 | O14: 5.6767677 | P14: 45.140562 | Q14: 402.25561 | R14: 201.76698 | S14: 111.99422 | T14: 62.489531 | U14: 734.25185 | V14: 387.18665 | W14: 0 | X14: 26.23861
A15: Ultimate Stress | B15: 60000 | C15: psi | F15: WT | K15: W | L15: W40X431 | M15: W40X431 | N15: 88.503937 | O15: 6.6508876 | P15: 54.038462 | Q15: 480.49845 | R15: 233.56408 | S15: 149.86667 | T15: 85.093785 | U15: 884.46309 | V15: 455.67316 | W15: 0 | X15: 21.612589
A16: Yield Stress | B16: 46000 | C16: psi | F16: MT | K16: W | L16: W40X397 | M16: W40X397 | N16: 96.068376 | O16: 7.2051282 | P16: 58.848168 | Q16: 527.49705 | R16: 256.52766 | S16: 174.14085 | T16: 96.569014 | U16: 975.71407 | V16: 501.67668 | W16: 0 | X16: 19.497808
F17: HSS | K17: W | L17: W40X372 | M17: W40X372 | N17: 102.18182 | O17: 7.6986301 | P17: 63.502825 | Q17: 569.52937 | R17: 271.37582 | S17: 198.63793 | T17: 112.4 | U17: 1059.0203 | V17: 537.4919 | W17: 0 | X17: 17.88538
A18: FSU | B18: 3 | F18: CHS | K18: W | L18: W40X362 | M18: W40X362 | N18: 106.03774 | O18: 7.915493 | P18: 64.971098 | Q18: 585.5433 | R18: 280.58329 | S18: 207.26972 | T18: 115.49358 | U18: 1090.6324 | V18: 555.16769 | W18: 0 | X18: 17.337985
A19: FSY | B19: 2 | F19: PIPE | K19: W | L19: W40X324 | M19: W40X324 | N19: 117.94334 | O19: 8.78125 | P19: 73.464052 | Q19: 659.17037 | R19: 316.125 | S19: 256.2267 | T19: 141.56171 | U19: 1241.1884 | V19: 632.45529 | W19: 0 | X19: 15.11359
K20: W | L20: W40X297 | M20: W40X297 | N20: 128.75143 | O20: 9.6068376 | P20: 81.449275 | Q20: 731.20934 | R20: 339.65888 | S20: 303.03922 | T20: 170.80392 | U20: 1388.4578 | V20: 694.22025 | W20: 0 | X20: 13.404471
A21: Ult Allowed | B21: =B15/B18 -> 20000 | C21: psi | K21: W | L21: W40X277 | M21: W40X277 | N21: 137.91411 | O21: 10.218182 | P21: 85.151515 | Q21: 769.53505 | R21: 379.67541 | S21: 344.83883 | T21: 181.14951 | U21: 1479.0928 | V21: 765.06669 | W21: 0 | X21: 12.521802
A22: Yield Allowed | B22: =B16/B19 -> 23000 | C22: psi | K22: W | L22: W40X249 | M22: W40X249 | N22: 152.92517 | O22: 11.319235 | P22: 95.254237 | Q22: 867.62693 | R22: 421.30884 | S22: 418.91864 | T22: 221.25984 | U22: 1688.8302 | V22: 864.12425 | W22: 0 | X22: 10.842517
K23: W | L23: W40X215 | M23: W40X215 | N23: 177.00787 | O23: 13.084983 | P23: 111.28713 | Q23: 1003.9197 | R23: 489.77614 | S23: 552.93548 | T23: 294.59677 | U23: 2007.8863 | V23: 1034.8109 | W23: 0 | X23: 8.9607235
A24: Beam Type | B24: W | K24: W | L24: W40X199 | M24: W40X199 | N24: 191.15646 | O24: 14.597403 | P24: 127.43764 | Q24: 1156.2698 | R24: 495.55808 | S24: 657.20219 | T24: 399.23497 | U24: 2327.5824 | V24: 1151.4841 | W24: 0 | X24: 7.5926066
K25: W | L25: W40X392 | M25: W40X392 | N25: 96.896552 | O25: 7.8055556 | P25: 86.461538 | Q25: 749.86657 | R25: 224.49291 | S25: 164.67907 | T25: 92.795349 | U25: 1343.4287 | V25: 462.13382 | W25: 0 | X25: 13.88728
K26: W | L26: W40X331 | M26: W40X331 | N26: 115.04606 | O26: 9.2892562 | P26: 106.03774 | Q26: 925.93241 | R26: 263.33842 | S26: 228.01143 | T26: 130.5981 | U26: 1667.6606 | V26: 558.82082 | W26: 0 | X26: 10.992848
K27: W | L27: W40X327 | M27: W40X327 | N27: 117.20542 | O27: 9.3666667 | P27: 107.04762 | Q27: 927.59683 | R27: 270.211 | S27: 232.43883 | T27: 128.76893 | U27: 1672.7131 | V27: 568.65142 | W27: 0 | X27: 10.956623
A28: Beam Profiles | K28: W | L28: W40X294 | M28: W40X294 | N28: 130.39443 | O28: 10.407407 | P28: 120.2139 | Q28: 1051.8135 | R28: 301.16654 | S28: 283.20104 | T28: 155.54047 | U28: 1904.645 | V28: 642.50415 | W28: 0 | X28: 9.5006447
A29: Useful Link: | B29: https://www.engineersedge.com/materials/aisc_structural_shapes/aisc_structural_shapes_viewer.htm | H29: [ | K29: W | L29: W40X278 | M29: W40X278 | N29: 136.57351 | O29: 11.019608 | P29: 129.04707 | Q29: 1132.3316 | R29: 312.4736 | S29: 312.99077 | T29: 178.11077 | U29: 2053.5199 | V29: 681.62994 | W29: 0 | X29: 8.739375
K30: W | L30: W40X264 | M30: W40X264 | N30: 145.21964 | O30: 11.575695 | P30: 136.07748 | Q30: 1199.2637 | R30: 334.9549 | S30: 346.61676 | T30: 192.34225 | U30: 2181.9496 | V30: 730.30504 | W30: 0 | X30: 8.1661145
K31: W | L31: W40X235 | M31: W40X235 | N31: 162.66281 | O31: 12.845714 | P31: 150.67024 | Q31: 1329.8552 | R31: 385.25135 | S31: 430.00484 | T31: 225.88862 | U31: 2442.6726 | V31: 839.47924 | W31: 0 | X31: 7.1877531
K32: W | L32: W40X211 | M32: W40X211 | N32: 180.99839 | O32: 14.300254 | P32: 170.04539 | Q32: 1501.914 | R32: 427.36172 | S32: 525.02632 | T32: 277.30263 | U32: 2779.869 | V32: 955.02912 | W32: 0 | X32: 6.1945837
K33: W | L33: W40X183 | M33: W40X183 | N33: 210.8818 | O33: 16.651852 | P33: 200.71429 | Q33: 1782.7795 | R33: 492.56876 | S33: 698.8601 | T33: 378.54922 | U33: 3344.1771 | V33: 1158.0876 | W33: 0 | X33: 4.9805445
K34: W | L34: W40X167 | M34: W40X167 | N34: 227.99189 | O34: 18.733333 | P34: 234.65553 | Q34: 2062.9867 | R34: 500.88064 | S34: 826.94286 | T34: 521.85714 | U34: 3879.5584 | V34: 1342.1536 | W34: 0 | X34: 4.1552259
D35: W, S, M, HP | K35: W | L35: W40X149 | M35: W40X149 | N35: 256.621 | O35: 21.910331 | P35: 289.69072 | Q35: 2563.5503 | R35: 524.31487 | S35: 996.7094 | T35: 756.53846 | U35: 4797.7636 | V35: 1692.5265 | W35: 0 | X35: 3.1686089
K36: W | L36: W36X925 | M36: W36X925 | N36: 41.323529 | O36: 3.3156342 | P36: 21.167608 | Q36: 171.02448 | R36: 105.02767 | S36: 35.606434 | T36: 23.737622 | U36: 309.64835 | V36: 197.77105 | W36: 0 | X36: 63.589396
K37: W | L37: W36X853 | M37: W36X853 | N37: 44.780876 | O37: 3.4584615 | P37: 22.257426 | Q37: 184.74422 | R37: 124.2517 | S37: 41.062258 | T37: 22.842581 | U37: 335.29002 | V37: 229.89258 | W37: 0 | X37: 58.649852
K38: W | L38: W36X802 | M38: W36X802 | N38: 47.627119 | O38: 3.6973684 | P38: 24.017094 | Q38: 199.77078 | R38: 132.64343 | S38: 45.923429 | T38: 25.477333 | U38: 362.94397 | V38: 245.77729 | W38: 0 | X38: 54.104924
K39: W | L39: W36X723 | M39: W36X723 | N39: 52.769953 | O39: 4.1021898 | P39: 27.019231 | Q39: 225.11157 | R39: 147.34641 | S39: 55.842038 | T39: 31.071083 | U39: 410.38814 | V39: 273.98338 | W39: 0 | X39: 47.734352
K40: W | L40: W36X652 | M40: W36X652 | N40: 58.541667 | O40: 4.5691057 | P40: 30.626703 | Q40: 254.60111 | R40: 163.49993 | S40: 67.09882 | T40: 37.340304 | U40: 465.57346 | V40: 305.23154 | W40: 0 | X40: 41.957775
...

Sheet W
CG1: Axial | CH1: Bending Stress | CJ1: Shear Stress | CL1: Torsional Stress | CN1: Combined Stress | CQ1: Min MS
CG2: Stress | CH2: X-axis | CI2: Y-axis | CJ2: X-axis | CK2: Y-axis | CL2: Flange | CM2: Web | CN2: Flange | CO2: Web
A3: Type | B3: EDI_Std_Nomenclature | C3: AISC_Manual_Label | D3: T_F | E3: W | F3: A | G3: d | H3: ddet | I3: Ht | J3: h | K3: OD | L3: bf | M3: bfdet | N3: B | O3: b | P3: ID | Q3: tw | R3: twdet | S3: twdet/2 | T3: tf | U3: tfdet | V3: t | W3: tnom | X3: tdes | Y3: kdes | Z3: kdet | AA3: k1 | AB3: x | AC3: y | AD3: eo | AE3: xp | AF3: yp | AG3: bf/2tf | AH3: b/t | AI3: b/tdes | AJ3: h/tw | AK3: h/tdes | AL3: D/t | AM3: Ix | AN3: Zx | AO3: Sx | AP3: rx | AQ3: Iy | AR3: Zy | AS3: Sy | AT3: ry | AU3: Iz | AV3: rz | AW3: Sz | AX3: J | AY3: Cw | AZ3: C | BA3: Wno | BB3: Sw1 | BC3: Sw2 | BD3: Sw3 | BE3: Qf | BF3: Qw | BG3: ro | BH3: H | BI3: tan(α) | BJ3: Iw | BK3: zA | BL3: zB | BM3: zC | BN3: wA | BO3: wB | BP3: wC | BQ3: SwA | BR3: SwB | BS3: SwC | BT3: SzA | BU3: SzB | BV3: SzC | BW3: rts | BX3: ho | BY3: PA | BZ3: PA2 | CA3: PB | CB3: PC | CC3: PD | CD3: T | CE3: WGi | CF3: WGo | CS3: Total Shear
A4: W | B4: W44X408 | C4: W44X408 | D4: T | E4: 408 | F4: 120 | G4: 44.8 | H4: 44.75 | I4: – | J4: – | K4: – | L4: 16.1 | M4: 16.125 | N4: – | O4: – | P4: – | Q4: 1.22 | R4: 1.25 | S4: 0.625 | T4: 2.17 | U4: 2.1875 | V4: – | W4: – | X4: – | Y4: 2.96 | Z4: 3.375 | AA4: 1.8125 | AB4: – | AC4: – | AD4: – | AE4: – | AF4: – | AG4: 3.71 | AH4: – | AI4: – | AJ4: 31.9 | AK4: – | AL4: – | AM4: 38700 | AN4: 2000 | AO4: 1730 | AP4: 18 | AQ4: 1520 | AR4: 297 | AS4: 189 | AT4: 3.56 | AU4: – | AV4: – | AW4: – | AX4: 134 | AY4: 691000 | AZ4: – | BA4: 172 | BB4: 1500 | BC4: – | BD4: – | BE4: 344 | BF4: 994 | BG4: – | BH4: – | BI4: – | BJ4: – | BK4: – | BL4: – | BM4: – | BN4: – | BO4: – | BP4: – | BQ4: – | BR4: – | BS4: – | BT4: – | BU4: – | BV4: – | BW4: 4.33 | BX4: 42.6 | BY4: 134 | BZ4: – | CA4: 150 | CB4: 106 | CC4: 122 | CD4: 38 | CE4: 5.5 | CF4: 3 | CG4: =Beams!$B$11/F4 -> 93.666667 | CH4: =Beams!$B$9/AO4 -> 6.4971098 | CI4: =Beams!$C$9/AS4 -> 59.470899 | CJ4: =Beams!$B$8*BE4/(AQ4*2*T4) -> 586.12661 | CK4: =Beams!$C$8*BF4/(AM4*Q4) -> 236.63659 | CL4: =Beams!$B$12*T4/AX4 -> 182.0209 | CM4: =Beams!$B$12*Q4/AX4 -> 102.33433 | CN4: =SQRT( (CG4 + CH4 + CI4)^2 + 3 * ( CJ4^2 + CL4^2 ) ) -> 1074.9471 | CO4: =SQRT( (CG4 + CH4 + CI4)^2 + 3 * ( CK4^2 + CM4^2 ) ) -> 474.22653 | CQ4: =MIN(Beams!$B$21:$B$22)/MAX(CN4:CP4)-1 -> 17.605567 | CR4: =Beams!$B$9/AO4 -> 6.4971098 | CS4: =SQRT( (Beams!$B$8 * BE4 / (AQ4 * T4))^2 + (Beams!$B$12 * Z4 / AX4)^2 ) -> 1205.9525 | CW4: =SQRT( ( (Beams!$B$11 / F4) )^2 + 3 * (SQRT( (Beams!$C$8 * BF4 / (AM4 * Q4))^2 + (Beams!$B$12 * Q4 / AX4)^2 ))^2 ) -> 456.26858 | CX4: =(Beams!$B$11 / F4) + (Beams!$B$9 * (G4/2 - T4/2) / AM4) + (Beams!$C$9 * (L4/2) / AQ4) -> 159.38501 | CY4: =SQRT( ( (Beams!$B$11 / F4) )^2 + 3 * (SQRT( (Beams!$C$8 * BF4 / (AM4 * Q4))^2 + (Beams!$B$12 * Q4 / AX4)^2 ))^2 ) -> 456.26858 | CZ4: =SQRT( ((Beams!$B$11 / F4) + (Beams!$B$9 * (G4/2) / AM4) + (Beams!$C$9 * (L4/2) / AQ4))^2 + 3 * (SQRT( (Beams!$B$8 * BE4 / (AQ4 * T4))^2 + (Beams!$B$12 * Z4 / AX4)^2 ))^2 ) -> 2094.8672
A5: W | B5: W44X368 | C5: W44X368 | D5: F | E5: 368 | F5: 108 | G5: 44.4 | H5: 44.375 | I5: – | J5: – | K5: – | L5: 16 | M5: 16 | N5: – | O5: – | P5: – | Q5: 1.1 | R5: 1.125 | S5: 0.5625 | T5: 1.97 | U5: 2 | V5: – | W5: – | X5: – | Y5: 2.76 | Z5: 3.1875 | AA5: 1.75 | AB5: – | AC5: – | AD5: – | AE5: – | AF5: – | AG5: 4.06 | AH5: – | AI5: – | AJ5: 35.4 | AK5: – | AL5: – | AM5: 34700 | AN5: 1800 | AO5: 1560 | AP5: 17.9 | AQ5: 1350 | AR5: 265 | AS5: 169 | AT5: 3.54 | AU5: – | AV5: – | AW5: – | AX5: 100 | AY5: 608000 | AZ5: – | BA5: 170 | BB5: 1340 | BC5: – | BD5: – | BE5: 311 | BF5: 894 | BG5: – | BH5: – | BI5: – | BJ5: – | BK5: – | BL5: – | BM5: – | BN5: – | BO5: – | BP5: – | BQ5: – | BR5: – | BS5: – | BT5: – | BU5: – | BV5: – | BW5: 4.28 | BX5: 42.4 | BY5: 133 | BZ5: – | CA5: 149 | CB5: 105 | CC5: 121 | CD5: 38 | CE5: 5.5 | CF5: 3 | CG5: =Beams!$B$11/F5 -> 104.07407 | CH5: =Beams!$B$9/AO5 -> 7.2051282 | CI5: =Beams!$C$9/AS5 -> 66.508876 | CJ5: =Beams!$B$8*BE5/(AQ5*2*T5) -> 657.19872 | CK5: =Beams!$C$8*BF5/(AM5*Q5) -> 263.25806 | CL5: =Beams!$B$12*T5/AX5 -> 221.428 | CM5: =Beams!$B$12*Q5/AX5 -> 123.64 | CN5: =SQRT( (CG5 + CH5 + CI5)^2 + 3 * ( CJ5^2 + CL5^2 ) ) -> 1214.2612 | CO5: =SQRT( (CG5 + CH5 + CI5)^2 + 3 * ( CK5^2 + CM5^2 ) ) -> 534.21303 | CQ5: =MIN(Beams!$B$21:$B$22)/MAX(CN5:CP5)-1 -> 15.470921 | CS5: =SQRT( (Beams!$B$8 * BE5 / (AQ5 * T5))^2 + (Beams!$B$12 * Z5 / AX5)^2 ) -> 1362.3515 | CT5: =(Beams!$B$11 / F4) + (Beams!$B$9 * (G4/2) / AM4) + (Beams!$C$9 * (L4/2) / AQ4) -> 159.70014 | CU5: =SQRT( ((Beams!$B$11 / F4) + (Beams!$B$9 * (G4/2) / AM4) + (Beams!$C$9 * (L4/2) / AQ4))^2 + 3 * (SQRT( (Beams!$B$8 * BE4 / (2*AQ4 * T4))^2 + (Beams!$B$12 * Z4 / AX4)^2 ))^2 ) -> 1138.6699 | CV5: =SQRT( ( (Beams!$B$11 / F4) )^2 + 3 * (SQRT( (Beams!$C$8 * BF4 / (AM4 * Q4))^2 + (Beams!$B$12 * Q4 / AX4)^2 ))^2 ) -> 456.26858
A6: W | B6: W44X335 | C6: W44X335 | D6: F | E6: 335 | F6: 98.5 | G6: 44 | H6: 44 | I6: – | J6: – | K6: – | L6: 15.9 | M6: 16 | N6: – | O6: – | P6: – | Q6: 1.03 | R6: 1 | S6: 0.5 | T6: 1.77 | U6: 1.75 | V6: – | W6: – | X6: – | Y6: 2.56 | Z6: 3 | AA6: 1.75 | AB6: – | AC6: – | AD6: – | AE6: – | AF6: – | AG6: 4.5 | AH6: – | AI6: – | AJ6: 38 | AK6: – | AL6: – | AM6: 31100 | AN6: 1620 | AO6: 1410 | AP6: 17.8 | AQ6: 1200 | AR6: 236 | AS6: 150 | AT6: 3.49 | AU6: – | AV6: – | AW6: – | AX6: 74.7 | AY6: 535000 | AZ6: – | BA6: 168 | BB6: 1180 | BC6: – | BD6: – | BE6: 278 | BF6: 805 | BG6: – | BH6: – | BI6: – | BJ6: – | BK6: – | BL6: – | BM6: – | BN6: – | BO6: – | BP6: – | BQ6: – | BR6: – | BS6: – | BT6: – | BU6: – | BV6: – | BW6: 4.24 | BX6: 42.2 | BY6: 132 | BZ6: – | CA6: 148 | CB6: 104 | CC6: 120 | CD6: 38 | CE6: 5.5 | CF6: 3 | CG6: =Beams!$B$11/F6 -> 114.11168 | CH6: =Beams!$B$9/AO6 -> 7.9716312 | CI6: =Beams!$C$9/AS6 -> 74.933333 | CJ6: =Beams!$B$8*BE6/(AQ6*2*T6) -> 735.57439 | CK6: =Beams!$C$8*BF6/(AM6*Q6) -> 282.46496 | CL6: =Beams!$B$12*T6/AX6 -> 266.32932 | CM6: =Beams!$B$12*Q6/AX6 -> 154.9826 | CN6: =SQRT( (CG6 + CH6 + CI6)^2 + 3 * ( CJ6^2 + CL6^2 ) ) -> 1369.2401 | CO6: =SQRT( (CG6 + CH6 + CI6)^2 + 3 * ( CK6^2 + CM6^2 ) ) -> 591.80548 | CQ6: =MIN(Beams!$B$21:$B$22)/MAX(CN6:CP6)-1 -> 13.606642 | CS6: =SQRT( (Beams!$B$8 * BE6 / (AQ6 * T6))^2 + (Beams!$B$12 * Z6 / AX6)^2 ) -> 1538.8456 | CT6: =(Beams!$B$11 / F5) + (Beams!$B$9 * (G5/2) / AM5) + (Beams!$C$9 * (L5/2) / AQ5) -> 177.87249 | CU6: =SQRT( ((Beams!$B$11 / F5) + (Beams!$B$9 * (G5/2) / AM5) + (Beams!$C$9 * (L5/2) / AQ5))^2 + 3 * (SQRT( (Beams!$B$8 * BE5 / (2*AQ5 * T5))^2 + (Beams!$B$12 * Z5 / AX5)^2 ))^2 ) -> 1308.6069 | CV6: =SQRT( ( (Beams!$B$11 / F5) )^2 + 3 * (SQRT( (Beams!$C$8 * BF5 / (AM5 * Q5))^2 + (Beams!$B$12 * Q5 / AX5)^2 ))^2 ) -> 514.39904
A7: W | B7: W44X290 | C7: W44X290 | D7: F | E7: 290 | F7: 85.4 | G7: 43.6 | H7: 43.625 | I7: – | J7: – | K7: – | L7: 15.8 | M7: 15.875 | N7: – | O7: – | P7: – | Q7: 0.865 | R7: 0.875 | S7: 0.4375 | T7: 1.58 | U7: 1.5625 | V7: – | W7: – | X7: – | Y7: 2.36 | Z7: 2.8125 | AA7: 1.625 | AB7: – | AC7: – | AD7: – | AE7: – | AF7: – | AG7: 5.02 | AH7: – | AI7: – | AJ7: 45 | AK7: – | AL7: – | AM7: 27000 | AN7: 1410 | AO7: 1240 | AP7: 17.8 | AQ7: 1040 | AR7: 205 | AS7: 132 | AT7: 3.49 | AU7: – | AV7: – | AW7: – | AX7: 50.9 | AY7: 461000 | AZ7: – | BA7: 166 | BB7: 1040 | BC7: – | BD7: – | BE7: 248 | BF7: 701 | BG7: – | BH7: – | BI7: – | BJ7: – | BK7: – | BL7: – | BM7: – | BN7: – | BO7: – | BP7: – | BQ7: – | BR7: – | BS7: – | BT7: – | BU7: – | BV7: – | BW7: 4.2 | BX7: 42 | BY7: 131 | BZ7: – | CA7: 147 | CB7: 103 | CC7: 119 | CD7: 38 | CE7: 5.5 | CF7: 3 | CG7: =Beams!$B$11/F7 -> 131.61593 | CH7: =Beams!$B$9/AO7 -> 9.0645161 | CI7: =Beams!$C$9/AS7 -> 85.151515 | CJ7: =Beams!$B$8*BE7/(AQ7*2*T7) -> 848.19864 | CK7: =Beams!$C$8*BF7/(AM7*Q7) -> 337.36844 | CL7: =Beams!$B$12*T7/AX7 -> 348.90373 | CM7: =Beams!$B$12*Q7/AX7 -> 191.01375 | CN7: =SQRT( (CG7 + CH7 + CI7)^2 + 3 * ( CJ7^2 + CL7^2 ) ) -> 1604.5324 | CO7: =SQRT( (CG7 + CH7 + CI7)^2 + 3 * ( CK7^2 + CM7^2 ) ) -> 708.45694 | CQ7: =MIN(Beams!$B$21:$B$22)/MAX(CN7:CP7)-1 -> 11.46469 | CS7: =SQRT( (Beams!$B$8 * BE7 / (AQ7 * T7))^2 + (Beams!$B$12 * Z7 / AX7)^2 ) -> 1806.5139 | CT7: =(Beams!$B$11 / F6) + (Beams!$B$9 * (G6/2) / AM6) + (Beams!$C$9 * (L6/2) / AQ6) -> 196.5278 | CU7: =SQRT( ((Beams!$B$11 / F6) + (Beams!$B$9 * (G6/2) / AM6) + (Beams!$C$9 * (L6/2) / AQ6))^2 + 3 * (SQRT( (Beams!$B$8 * BE6 / (2*AQ6 * T6))^2 + (Beams!$B$12 * Z6 / AX6)^2 ))^2 ) -> 1507.6914 | CV7: =SQRT( ( (Beams!$B$11 / F6) )^2 + 3 * (SQRT( (Beams!$C$8 * BF6 / (AM6 * Q6))^2 + (Beams!$B$12 * Q6 / AX6)^2 ))^2 ) -> 569.59604
A8: W | B8: W44X262 | C8: W44X262 | D8: F | E8: 262 | F8: 77.2 | G8: 43.3 | H8: 43.25 | I8: – | J8: – | K8: – | L8: 15.8 | M8: 15.75 | N8: – | O8: – | P8: – | Q8: 0.785 | R8: 0.8125 | S8: 0.4375 | T8: 1.42 | U8: 1.4375 | V8: – | W8: – | X8: – | Y8: 2.2 | Z8: 2.625 | AA8: 1.625 | AB8: – | AC8: – | AD8: – | AE8: – | AF8: – | AG8: 5.57 | AH8: – | AI8: – | AJ8: 49.6 | AK8: – | AL8: – | AM8: 24100 | AN8: 1270 | AO8: 1110 | AP8: 17.7 | AQ8: 923 | AR8: 182 | AS8: 117 | AT8: 3.47 | AU8: – | AV8: – | AW8: – | AX8: 37.3 | AY8: 405000 | AZ8: – | BA8: 165 | BB8: 928 | BC8: – | BD8: – | BE8: 223 | BF8: 630 | BG8: – | BH8: – | BI8: – | BJ8: – | BK8: – | BL8: – | BM8: – | BN8: – | BO8: – | BP8: – | BQ8: – | BR8: – | BS8: – | BT8: – | BU8: – | BV8: – | BW8: 4.17 | BX8: 41.9 | BY8: 131 | BZ8: – | CA8: 147 | CB8: 102 | CC8: 118 | CD8: 38 | CE8: 5.5 | CF8: 3 | CG8: =Beams!$B$11/F8 -> 145.59585 | CH8: =Beams!$B$9/AO8 -> 10.126126 | CI8: =Beams!$C$9/AS8 -> 96.068376 | CJ8: =Beams!$B$8*BE8/(AQ8*2*T8) -> 956.20527 | CK8: =Beams!$C$8*BF8/(AM8*Q8) -> 374.30029 | CL8: =Beams!$B$12*T8/AX8 -> 427.90349 | CM8: =Beams!$B$12*Q8/AX8 -> 236.55228 | CN8: =SQRT( (CG8 + CH8 + CI8)^2 + 3 * ( CJ8^2 + CL8^2 ) ) -> 1831.8537 | CO8: =SQRT( (CG8 + CH8 + CI8)^2 + 3 * ( CK8^2 + CM8^2 ) ) -> 807.19975 | CQ8: =MIN(Beams!$B$21:$B$22)/MAX(CN8:CP8)-1 -> 9.9179022 | CS8: =SQRT( (Beams!$B$8 * BE8 / (AQ8 * T8))^2 + (Beams!$B$12 * Z8 / AX8)^2 ) -> 2069.547 | CT8: =(Beams!$B$11 / F7) + (Beams!$B$9 * (G7/2) / AM7) + (Beams!$C$9 * (L7/2) / AQ7) -> 226.07195 | CU8: =SQRT( ((Beams!$B$11 / F7) + (Beams!$B$9 * (G7/2) / AM7) + (Beams!$C$9 * (L7/2) / AQ7))^2 + 3 * (SQRT( (Beams!$B$8 * BE7 / (2*AQ7 * T7))^2 + (Beams!$B$12 * Z7 / AX7)^2 ))^2 ) -> 1834.8346 | CV8: =SQRT( ( (Beams!$B$11 / F7) )^2 + 3 * (SQRT( (Beams!$C$8 * BF7 / (AM7 * Q7))^2 + (Beams!$B$12 * Q7 / AX7)^2 ))^2 ) -> 684.2762
A9: W | B9: W44X230 | C9: W44X230 | D9: F | E9: 230 | F9: 67.8 | G9: 42.9 | H9: 42.875 | I9: – | J9: – | K9: – | L9: 15.8 | M9: 15.75 | N9: – | O9: – | P9: – | Q9: 0.71 | R9: 0.6875 | S9: 0.375 | T9: 1.22 | U9: 1.25 | V9: – | W9: – | X9: – | Y9: 2.01 | Z9: 2.4375 | AA9: 1.5625 | AB9: – | AC9: – | AD9: – | AE9: – | AF9: – | AG9: 6.45 | AH9: – | AI9: – | AJ9: 54.8 | AK9: – | AL9: – | AM9: 20800 | AN9: 1100 | AO9: 971 | AP9: 17.5 | AQ9: 796 | AR9: 157 | AS9: 101 | AT9: 3.43 | AU9: – | AV9: – | AW9: – | AX9: 24.9 | AY9: 346000 | AZ9: – | BA9: 165 | BB9: 793 | BC9: – | BD9: – | BE9: 192 | BF9: 547 | BG9: – | BH9: – | BI9: – | BJ9: – | BK9: – | BL9: – | BM9: – | BN9: – | BO9: – | BP9: – | BQ9: – | BR9: – | BS9: – | BT9: – | BU9: – | BV9: – | BW9: 4.13 | BX9: 41.7 | BY9: 130 | BZ9: – | CA9: 146 | CB9: 102 | CC9: 118 | CD9: 38 | CE9: 5.5 | CF9: 3 | CG9: =Beams!$B$11/F9 -> 165.78171 | CH9: =Beams!$B$9/AO9 -> 11.575695 | CI9: =Beams!$C$9/AS9 -> 111.28713 | CJ9: =Beams!$B$8*BE9/(AQ9*2*T9) -> 1111.1294 | CK9: =Beams!$C$8*BF9/(AM9*Q9) -> 416.32449 | CL9: =Beams!$B$12*T9/AX9 -> 550.71486 | CM9: =Beams!$B$12*Q9/AX9 -> 320.49799 | CN9: =SQRT( (CG9 + CH9 + CI9)^2 + 3 * ( CJ9^2 + CL9^2 ) ) -> 2167.2568 | CO9: =SQRT( (CG9 + CH9 + CI9)^2 + 3 * ( CK9^2 + CM9^2 ) ) -> 954.69932 | CQ9: =MIN(Beams!$B$21:$B$22)/MAX(CN9:CP9)-1 -> 8.2282558 | CT9: =(Beams!$B$11 / F8) + (Beams!$B$9 * (G8/2) / AM8) + (Beams!$C$9 * (L8/2) / AQ8) -> 251.89688 | CU9: =SQRT( ((Beams!$B$11 / F8) + (Beams!$B$9 * (G8/2) / AM8) + (Beams!$C$9 * (L8/2) / AQ8))^2 + 3 * (SQRT( (Beams!$B$8 * BE8 / (2*AQ8 * T8))^2 + (Beams!$B$12 * Z8 / AX8)^2 ))^2 ) -> 2164.1556 | CV9: =SQRT( ( (Beams!$B$11 / F8) )^2 + 3 * (SQRT( (Beams!$C$8 * BF8 / (AM8 * Q8))^2 + (Beams!$B$12 * Q8 / AX8)^2 ))^2 ) -> 780.62232
A10: W | B10: W40X655 | C10: W40X655 | D10: T | E10: 655 | F10: 193 | G10: 43.6 | H10: 43.625 | I10: – | J10: – | K10: – | L10: 16.9 | M10: 16.875 | N10: – | O10: – | P10: – | Q10: 1.97 | R10: 2 | S10: 1 | T10: 3.54 | U10: 3.5625 | V10: – | W10: – | X10: – | Y10: 4.72 | Z10: 4.8125 | AA10: 2.1875 | AB10: – | AC10: – | AD10: – | AE10: – | AF10: – | AG10: 2.39 | AH10: – | AI10: – | AJ10: 17.3 | AK10: – | AL10: – | AM10: 56500 | AN10: 3080 | AO10: 2590 | AP10: 17.1 | AQ10: 2870 | AR10: 542 | AS10: 340 | AT10: 3.86 | AU10: – | AV10: – | AW10: – | AX10: 589 | AY10: 1150000 | AZ10: – | BA10: 169 | BB10: 2530 | BC10: – | BD10: – | BE10: 529 | BF10: 1530 | BG10: – | BH10: – | BI10: – | BJ10: – | BK10: – | BL10: – | BM10: – | BN10: – | BO10: – | BP10: – | BQ10: – | BR10: – | BS10: – | BT10: – | BU10: – | BV10: – | BW10: 4.71 | BX10: 40.1 | BY10: 132 | BZ10: – | CA10: 149 | CB10: 104 | CC10: 121 | CD10: 34 | CE10: 7.5 | CF10: 3 | CG10: =Beams!$B$11/F10 -> 58.238342 | CH10: =Beams!$B$9/AO10 -> 4.3397683 | CI10: =Beams!$C$9/AS10 -> 33.058824 | CJ10: =Beams!$B$8*BE10/(AQ10*2*T10) -> 292.6219 | CK10: =Beams!$C$8*BF10/(AM10*Q10) -> 154.50519 | CL10: =Beams!$B$12*T10/AX10 -> 67.554499 | CM10: =Beams!$B$12*Q10/AX10 -> 37.593888 | CN10: =SQRT( (CG10 + CH10 + CI10)^2 + 3 * ( CJ10^2 + CL10^2 ) ) -> 528.88561 | CO10: =SQRT( (CG10 + CH10 + CI10)^2 + 3 * ( CK10^2 + CM10^2 ) ) -> 291.55083 | CQ10: =MIN(Beams!$B$21:$B$22)/MAX(CN10:CP10)-1 -> 36.815361
A11: W | B11: W40X593 | C11: W40X593 | D11: T | E11: 593 | F11: 174 | G11: 43 | H11: 43 | I11: – | J11: – | K11: – | L11: 16.7 | M11: 16.75 | N11: – | O11: – | P11: – | Q11: 1.79 | R11: 1.8125 | S11: 0.9375 | T11: 3.23 | U11: 3.25 | V11: – | W11: – | X11: – | Y11: 4.41 | Z11: 4.5 | AA11: 2.125 | AB11: – | AC11: – | AD11: – | AE11: – | AF11: – | AG11: 2.58 | AH11: – | AI11: – | AJ11: 19.1 | AK11: – | AL11: – | AM11: 50400 | AN11: 2760 | AO11: 2340 | AP11: 17 | AQ11: 2520 | AR11: 481 | AS11: 302 | AT11: 3.8 | AU11: – | AV11: – | AW11: – | AX11: 445 | AY11: 997000 | AZ11: – | BA11: 166 | BB11: 2240 | BC11: – | BD11: – | BE11: 479 | BF11: 1370 | BG11: – | BH11: – | BI11: – | BJ11: – | BK11: – | BL11: – | BM11: – | BN11: – | BO11: – | BP11: – | BQ11: – | BR11: – | BS11: – | BT11: – | BU11: – | BV11: – | BW11: 4.63 | BX11: 39.8 | BY11: 130 | BZ11: – | CA11: 147 | CB11: 103 | CC11: 120 | CD11: 34 | CE11: 7.5 | CF11: 3 | CG11: =Beams!$B$11/F11 -> 64.597701 | CH11: =Beams!$B$9/AO11 -> 4.8034188 | CI11: =Beams!$C$9/AS11 -> 37.218543 | CJ11: =Beams!$B$8*BE11/(AQ11*2*T11) -> 330.72633 | CK11: =Beams!$C$8*BF11/(AM11*Q11) -> 170.68813 | CL11: =Beams!$B$12*T11/AX11 -> 81.584719 | CM11: =Beams!$B$12*Q11/AX11 -> 45.212584 | CN11: =SQRT( (CG11 + CH11 + CI11)^2 + 3 * ( CJ11^2 + CL11^2 ) ) -> 599.56289 | CO11: =SQRT( (CG11 + CH11 + CI11)^2 + 3 * ( CK11^2 + CM11^2 ) ) -> 323.88824 | CQ11: =MIN(Beams!$B$21:$B$22)/MAX(CN11:CP11)-1 -> 32.357635
A12: W | B12: W40X503 | C12: W40X503 | D12: T | E12: 503 | F12: 148 | G12: 42.1 | H12: 42 | I12: – | J12: – | K12: – | L12: 16.4 | M12: 16.375 | N12: – | O12: – | P12: – | Q12: 1.54 | R12: 1.5625 | S12: 0.8125 | T12: 2.76 | U12: 2.75 | V12: – | W12: – | X12: – | Y12: 3.94 | Z12: 4 | AA12: 2 | AB12: – | AC12: – | AD12: – | AE12: – | AF12: – | AG12: 2.98 | AH12: – | AI12: – | AJ12: 22.3 | AK12: – | AL12: – | AM12: 41600 | AN12: 2320 | AO12: 1980 | AP12: 16.8 | AQ12: 2040 | AR12: 394 | AS12: 249 | AT12: 3.72 | AU12: – | AV12: – | AW12: – | AX12: 277 | AY12: 789000 | AZ12: – | BA12: 161 | BB12: 1830 | BC12: – | BD12: – | BE12: 403 | BF12: 1150 | BG12: – | BH12: – | BI12: – | BJ12: – | BK12: – | BL12: – | BM12: – | BN12: – | BO12: – | BP12: – | BQ12: – | BR12: – | BS12: – | BT12: – | BU12: – | BV12: – | BW12: 4.5 | BX12: 39.3 | BY12: 129 | BZ12: – | CA12: 145 | CB12: 101 | CC12: 117 | CD12: 34 | CE12: 7.5 | CF12: 3 | CG12: =Beams!$B$11/F12 -> 75.945946 | CH12: =Beams!$B$9/AO12 -> 5.6767677 | CI12: =Beams!$C$9/AS12 -> 45.140562 | CJ12: =Beams!$B$8*BE12/(AQ12*2*T12) -> 402.25561 | CK12: =Beams!$C$8*BF12/(AM12*Q12) -> 201.76698 | CL12: =Beams!$B$12*T12/AX12 -> 111.99422 | CM12: =Beams!$B$12*Q12/AX12 -> 62.489531 | CN12: =SQRT( (CG12 + CH12 + CI12)^2 + 3 * ( CJ12^2 + CL12^2 ) ) -> 734.25185 | CO12: =SQRT( (CG12 + CH12 + CI12)^2 + 3 * ( CK12^2 + CM12^2 ) ) -> 387.18665 | CQ12: =MIN(Beams!$B$21:$B$22)/MAX(CN12:CP12)-1 -> 26.23861
A13: W | B13: W40X431 | C13: W40X431 | D13: T | E13: 431 | F13: 127 | G13: 41.3 | H13: 41.25 | I13: – | J13: – | K13: – | L13: 16.2 | M13: 16.25 | N13: – | O13: – | P13: – | Q13: 1.34 | R13: 1.3125 | S13: 0.6875 | T13: 2.36 | U13: 2.375 | V13: – | W13: – | X13: – | Y13: 3.54 | Z13: 3.625 | AA13: 1.875 | AB13: – | AC13: – | AD13: – | AE13: – | AF13: – | AG13: 3.44 | AH13: – | AI13: – | AJ13: 25.5 | AK13: – | AL13: – | AM13: 34800 | AN13: 1960 | AO13: 1690 | AP13: 16.6 | AQ13: 1690 | AR13: 328 | AS13: 208 | AT13: 3.65 | AU13: – | AV13: – | AW13: – | AX13: 177 | AY13: 638000 | AZ13: – | BA13: 158 | BB13: 1510 | BC13: – | BD13: – | BE13: 341 | BF13: 969 | BG13: – | BH13: – | BI13: – | BJ13: – | BK13: – | BL13: – | BM13: – | BN13: – | BO13: – | BP13: – | BQ13: – | BR13: – | BS13: – | BT13: – | BU13: – | BV13: – | BW13: 4.41 | BX13: 38.9 | BY13: 127 | BZ13: – | CA13: 143 | CB13: 98.8 | CC13: 115 | CD13: 34 | CE13: 7.5 | CF13: 3 | CG13: =Beams!$B$11/F13 -> 88.503937 | CH13: =Beams!$B$9/AO13 -> 6.6508876 | CI13: =Beams!$C$9/AS13 -> 54.038462 | CJ13: =Beams!$B$8*BE13/(AQ13*2*T13) -> 480.49845 | CK13: =Beams!$C$8*BF13/(AM13*Q13) -> 233.56408 | CL13: =Beams!$B$12*T13/AX13 -> 149.86667 | CM13: =Beams!$B$12*Q13/AX13 -> 85.093785 | CN13: =SQRT( (CG13 + CH13 + CI13)^2 + 3 * ( CJ13^2 + CL13^2 ) ) -> 884.46309 | CO13: =SQRT( (CG13 + CH13 + CI13)^2 + 3 * ( CK13^2 + CM13^2 ) ) -> 455.67316 | CQ13: =MIN(Beams!$B$21:$B$22)/MAX(CN13:CP13)-1 -> 21.612589
A14: W | B14: W40X397 | C14: W40X397 | D14: T | E14: 397 | F14: 117 | G14: 41 | H14: 41 | I14: – | J14: – | K14: – | L14: 16.1 | M14: 16.125 | N14: – | O14: – | P14: – | Q14: 1.22 | R14: 1.25 | S14: 0.625 | T14: 2.2 | U14: 2.1875 | V14: – | W14: – | X14: – | Y14: 3.38 | Z14: 3.5 | AA14: 1.8125 | AB14: – | AC14: – | AD14: – | AE14: – | AF14: – | AG14: 3.66 | AH14: – | AI14: – | AJ14: 28 | AK14: – | AL14: – | AM14: 32000 | AN14: 1800 | AO14: 1560 | AP14: 16.6 | AQ14: 1540 | AR14: 300 | AS14: 191 | AT14: 3.64 | AU14: – | AV14: – | AW14: – | AX14: 142 | AY14: 579000 | AZ14: – | BA14: 156 | BB14: 1380 | BC14: – | BD14: – | BE14: 318 | BF14: 891 | BG14: – | BH14: – | BI14: – | BJ14: – | BK14: – | BL14: – | BM14: – | BN14: – | BO14: – | BP14: – | BQ14: – | BR14: – | BS14: – | BT14: – | BU14: – | BV14: – | BW14: 4.38 | BX14: 38.8 | BY14: 126 | BZ14: – | CA14: 142 | CB14: 98.1 | CC14: 114 | CD14: 34 | CE14: 7.5 | CF14: 3 | CG14: =Beams!$B$11/F14 -> 96.068376 | CH14: =Beams!$B$9/AO14 -> 7.2051282 | CI14: =Beams!$C$9/AS14 -> 58.848168 | CJ14: =Beams!$B$8*BE14/(AQ14*2*T14) -> 527.49705 | CK14: =Beams!$C$8*BF14/(AM14*Q14) -> 256.52766 | CL14: =Beams!$B$12*T14/AX14 -> 174.14085 | CM14: =Beams!$B$12*Q14/AX14 -> 96.569014 | CN14: =SQRT( (CG14 + CH14 + CI14)^2 + 3 * ( CJ14^2 + CL14^2 ) ) -> 975.71407 | CO14: =SQRT( (CG14 + CH14 + CI14)^2 + 3 * ( CK14^2 + CM14^2 ) ) -> 501.67668 | CQ14: =MIN(Beams!$B$21:$B$22)/MAX(CN14:CP14)-1 -> 19.497808
A15: W | B15: W40X372 | C15: W40X372 | D15: T | E15: 372 | F15: 110 | G15: 40.6 | H15: 40.625 | I15: – | J15: – | K15: – | L15: 16.1 | M15: 16.125 | N15: – | O15: – | P15: – | Q15: 1.16 | R15: 1.1875 | S15: 0.625 | T15: 2.05 | U15: 2.0625 | V15: – | W15: – | X15: – | Y15: 3.23 | Z15: 3.3125 | AA15: 1.8125 | AB15: – | AC15: – | AD15: – | AE15: – | AF15: – | AG15: 3.93 | AH15: – | AI15: – | AJ15: 29.5 | AK15: – | AL15: – | AM15: 29600 | AN15: 1680 | AO15: 1460 | AP15: 16.5 | AQ15: 1420 | AR15: 277 | AS15: 177 | AT15: 3.6 | AU15: – | AV15: – | AW15: – | AX15: 116 | AY15: 528000 | AZ15: – | BA15: 155 | BB15: 1280 | BC15: – | BD15: – | BE15: 295 | BF15: 829 | BG15: – | BH15: – | BI15: – | BJ15: – | BK15: – | BL15: – | BM15: – | BN15: – | BO15: – | BP15: – | BQ15: – | BR15: – | BS15: – | BT15: – | BU15: – | BV15: – | BW15: 4.33 | BX15: 38.6 | BY15: 125 | BZ15: – | CA15: 141 | CB15: 97.3 | CC15: 113 | CD15: 34 | CE15: 7.5 | CF15: 3 | CG15: =Beams!$B$11/F15 -> 102.18182 | CH15: =Beams!$B$9/AO15 -> 7.6986301 | CI15: =Beams!$C$9/AS15 -> 63.502825 | CJ15: =Beams!$B$8*BE15/(AQ15*2*T15) -> 569.52937 | CK15: =Beams!$C$8*BF15/(AM15*Q15) -> 271.37582 | CL15: =Beams!$B$12*T15/AX15 -> 198.63793 | CM15: =Beams!$B$12*Q15/AX15 -> 112.4 | CN15: =SQRT( (CG15 + CH15 + CI15)^2 + 3 * ( CJ15^2 + CL15^2 ) ) -> 1059.0203 | CO15: =SQRT( (CG15 + CH15 + CI15)^2 + 3 * ( CK15^2 + CM15^2 ) ) -> 537.4919 | CQ15: =MIN(Beams!$B$21:$B$22)/MAX(CN15:CP15)-1 -> 17.88538
A16: W | B16: W40X362 | C16: W40X362 | D16: T | E16: 362 | F16: 106 | G16: 40.6 | H16: 40.5 | I16: – | J16: – | K16: – | L16: 16 | M16: 16 | N16: – | O16: – | P16: – | Q16: 1.12 | R16: 1.125 | S16: 0.5625 | T16: 2.01 | U16: 2 | V16: – | W16: – | X16: – | Y16: 3.19 | Z16: 3.25 | AA16: 1.75 | AB16: – | AC16: – | AD16: – | AE16: – | AF16: – | AG16: 3.99 | AH16: – | AI16: – | AJ16: 30.5 | AK16: – | AL16: – | AM16: 28900 | AN16: 1640 | AO16: 1420 | AP16: 16.5 | AQ16: 1380 | AR16: 270 | AS16: 173 | AT16: 3.6 | AU16: – | AV16: – | AW16: – | AX16: 109 | AY16: 513000 | AZ16: – | BA16: 154 | BB16: 1240 | BC16: – | BD16: – | BE16: 289 | BF16: 808 | BG16: – | BH16: – | BI16: – | BJ16: – | BK16: – | BL16: – | BM16: – | BN16: – | BO16: – | BP16: – | BQ16: – | BR16: – | BS16: – | BT16: – | BU16: – | BV16: – | BW16: 4.33 | BX16: 38.6 | BY16: 125 | BZ16: – | CA16: 141 | CB16: 97.2 | CC16: 113 | CD16: 34 | CE16: 7.5 | CF16: 3 | CG16: =Beams!$B$11/F16 -> 106.03774 | CH16: =Beams!$B$9/AO16 -> 7.915493 | CI16: =Beams!$C$9/AS16 -> 64.971098 | CJ16: =Beams!$B$8*BE16/(AQ16*2*T16) -> 585.5433 | CK16: =Beams!$C$8*BF16/(AM16*Q16) -> 280.58329 | CL16: =Beams!$B$12*T16/AX16 -> 207.26972 | CM16: =Beams!$B$12*Q16/AX16 -> 115.49358 | CN16: =SQRT( (CG16 + CH16 + CI16)^2 + 3 * ( CJ16^2 + CL16^2 ) ) -> 1090.6324 | CO16: =SQRT( (CG16 + CH16 + CI16)^2 + 3 * ( CK16^2 + CM16^2 ) ) -> 555.16769 | CQ16: =MIN(Beams!$B$21:$B$22)/MAX(CN16:CP16)-1 -> 17.337985
A17: W | B17: W40X324 | C17: W40X324 | D17: F | E17: 324 | F17: 95.3 | G17: 40.2 | H17: 40.125 | I17: – | J17: – | K17: – | L17: 15.9 | M17: 15.875 | N17: – | O17: – | P17: – | Q17: 1 | R17: 1 | S17: 0.5 | T17: 1.81 | U17: 1.8125 | V17: – | W17: – | X17: – | Y17: 2.99 | Z17: 3.0625 | AA17: 1.6875 | AB17: – | AC17: – | AD17: – | AE17: – | AF17: – | AG17: 4.4 | AH17: – | AI17: – | AJ17: 34.2 | AK17: – | AL17: – | AM17: 25600 | AN17: 1460 | AO17: 1280 | AP17: 16.4 | AQ17: 1220 | AR17: 239 | AS17: 153 | AT17: 3.58 | AU17: – | AV17: – | AW17: – | AX17: 79.4 | AY17: 448000 | AZ17: – | BA17: 153 | BB17: 1100 | BC17: – | BD17: – | BE17: 259 | BF17: 720 | BG17: – | BH17: – | BI17: – | BJ17: – | BK17: – | BL17: – | BM17: – | BN17: – | BO17: – | BP17: – | BQ17: – | BR17: – | BS17: – | BT17: – | BU17: – | BV17: – | BW17: 4.27 | BX17: 38.4 | BY17: 124 | BZ17: – | CA17: 140 | CB17: 96.3 | CC17: 112 | CD17: 34 | CE17: 7.5 | CF17: 3 | CG17: =Beams!$B$11/F17 -> 117.94334 | CH17: =Beams!$B$9/AO17 -> 8.78125 | CI17: =Beams!$C$9/AS17 -> 73.464052 | CJ17: =Beams!$B$8*BE17/(AQ17*2*T17) -> 659.17037 | CK17: =Beams!$C$8*BF17/(AM17*Q17) -> 316.125 | CL17: =Beams!$B$12*T17/AX17 -> 256.2267 | CM17: =Beams!$B$12*Q17/AX17 -> 141.56171 | CN17: =SQRT( (CG17 + CH17 + CI17)^2 + 3 * ( CJ17^2 + CL17^2 ) ) -> 1241.1884 | CO17: =SQRT( (CG17 + CH17 + CI17)^2 + 3 * ( CK17^2 + CM17^2 ) ) -> 632.45529 | CQ17: =MIN(Beams!$B$21:$B$22)/MAX(CN17:CP17)-1 -> 15.11359
A18: W | B18: W40X297 | C18: W40X297 | D18: F | E18: 297 | F18: 87.3 | G18: 39.8 | H18: 39.875 | I18: – | J18: – | K18: – | L18: 15.8 | M18: 15.875 | N18: – | O18: – | P18: – | Q18: 0.93 | R18: 0.9375 | S18: 0.5 | T18: 1.65 | U18: 1.625 | V18: – | W18: – | X18: – | Y18: 2.83 | Z18: 2.9375 | AA18: 1.6875 | AB18: – | AC18: – | AD18: – | AE18: – | AF18: – | AG18: 4.8 | AH18: – | AI18: – | AJ18: 36.8 | AK18: – | AL18: – | AM18: 23200 | AN18: 1330 | AO18: 1170 | AP18: 16.3 | AQ18: 1090 | AR18: 215 | AS18: 138 | AT18: 3.54 | AU18: – | AV18: – | AW18: – | AX18: 61.2 | AY18: 399000 | AZ18: – | BA18: 151 | BB18: 982 | BC18: – | BD18: – | BE18: 234 | BF18: 652 | BG18: – | BH18: – | BI18: – | BJ18: – | BK18: – | BL18: – | BM18: – | BN18: – | BO18: – | BP18: – | BQ18: – | BR18: – | BS18: – | BT18: – | BU18: – | BV18: – | BW18: 4.22 | BX18: 38.2 | BY18: 123 | BZ18: – | CA18: 139 | CB18: 95.4 | CC18: 111 | CD18: 34 | CE18: 7.5 | CF18: 3 | CG18: =Beams!$B$11/F18 -> 128.75143 | CH18: =Beams!$B$9/AO18 -> 9.6068376 | CI18: =Beams!$C$9/AS18 -> 81.449275 | CJ18: =Beams!$B$8*BE18/(AQ18*2*T18) -> 731.20934 | CK18: =Beams!$C$8*BF18/(AM18*Q18) -> 339.65888 | CL18: =Beams!$B$12*T18/AX18 -> 303.03922 | CM18: =Beams!$B$12*Q18/AX18 -> 170.80392 | CN18: =SQRT( (CG18 + CH18 + CI18)^2 + 3 * ( CJ18^2 + CL18^2 ) ) -> 1388.4578 | CO18: =SQRT( (CG18 + CH18 + CI18)^2 + 3 * ( CK18^2 + CM18^2 ) ) -> 694.22025 | CQ18: =MIN(Beams!$B$21:$B$22)/MAX(CN18:CP18)-1 -> 13.404471
A19: W | B19: W40X277 | C19: W40X277 | D19: F | E19: 277 | F19: 81.5 | G19: 39.7 | H19: 39.75 | I19: – | J19: – | K19: – | L19: 15.8 | M19: 15.875 | N19: – | O19: – | P19: – | Q19: 0.83 | R19: 0.8125 | S19: 0.4375 | T19: 1.58 | U19: 1.5625 | V19: – | W19: – | X19: – | Y19: 2.76 | Z19: 2.875 | AA19: 1.625 | AB19: – | AC19: – | AD19: – | AE19: – | AF19: – | AG19: 5.03 | AH19: – | AI19: – | AJ19: 41.2 | AK19: – | AL19: – | AM19: 21900 | AN19: 1250 | AO19: 1100 | AP19: 16.4 | AQ19: 1040 | AR19: 204 | AS19: 132 | AT19: 3.58 | AU19: – | AV19: – | AW19: – | AX19: 51.5 | AY19: 379000 | AZ19: – | BA19: 151 | BB19: 940 | BC19: – | BD19: – | BE19: 225 | BF19: 614 | BG19: – | BH19: – | BI19: – | BJ19: – | BK19: – | BL19: – | BM19: – | BN19: – | BO19: – | BP19: – | BQ19: – | BR19: – | BS19: – | BT19: – | BU19: – | BV19: – | BW19: 4.25 | BX19: 38.1 | BY19: 123 | BZ19: – | CA19: 139 | CB19: 95.2 | CC19: 111 | CD19: 34 | CE19: 7.5 | CF19: 3 | CG19: =Beams!$B$11/F19 -> 137.91411 | CH19: =Beams!$B$9/AO19 -> 10.218182 | CI19: =Beams!$C$9/AS19 -> 85.151515 | CJ19: =Beams!$B$8*BE19/(AQ19*2*T19) -> 769.53505 | CK19: =Beams!$C$8*BF19/(AM19*Q19) -> 379.67541 | CL19: =Beams!$B$12*T19/AX19 -> 344.83883 | CM19: =Beams!$B$12*Q19/AX19 -> 181.14951 | CN19: =SQRT( (CG19 + CH19 + CI19)^2 + 3 * ( CJ19^2 + CL19^2 ) ) -> 1479.0928 | CO19: =SQRT( (CG19 + CH19 + CI19)^2 + 3 * ( CK19^2 + CM19^2 ) ) -> 765.06669 | CQ19: =MIN(Beams!$B$21:$B$22)/MAX(CN19:CP19)-1 -> 12.521802
A20: W | B20: W40X249 | C20: W40X249 | D20: F | E20: 249 | F20: 73.5 | G20: 39.4 | H20: 39.375 | I20: – | J20: – | K20: – | L20: 15.8 | M20: 15.75 | N20: – | O20: – | P20: – | Q20: 0.75 | R20: 0.75 | S20: 0.375 | T20: 1.42 | U20: 1.4375 | V20: – | W20: – | X20: – | Y20: 2.6 | Z20: 2.6875 | AA20: 1.5625 | AB20: – | AC20: – | AD20: – | AE20: – | AF20: – | AG20: 5.55 | AH20: – | AI20: – | AJ20: 45.6 | AK20: – | AL20: – | AM20: 19600 | AN20: 1120 | AO20: 993 | AP20: 16.3 | AQ20: 926 | AR20: 182 | AS20: 118 | AT20: 3.55 | AU20: – | AV20: – | AW20: – | AX20: 38.1 | AY20: 334000 | AZ20: – | BA20: 150 | BB20: 841 | BC20: – | BD20: – | BE20: 203 | BF20: 551 | BG20: – | BH20: – | BI20: – | BJ20: – | BK20: – | BL20: – | BM20: – | BN20: – | BO20: – | BP20: – | BQ20: – | BR20: – | BS20: – | BT20: – | BU20: – | BV20: – | BW20: 4.21 | BX20: 38 | BY20: 122 | BZ20: – | CA20: 138 | CB20: 94.6 | CC20: 110 | CD20: 34 | CE20: 7.5 | CF20: 3 | CG20: =Beams!$B$11/F20 -> 152.92517 | CH20: =Beams!$B$9/AO20 -> 11.319235 | CI20: =Beams!$C$9/AS20 -> 95.254237 | CJ20: =Beams!$B$8*BE20/(AQ20*2*T20) -> 867.62693 | CK20: =Beams!$C$8*BF20/(AM20*Q20) -> 421.30884 | CL20: =Beams!$B$12*T20/AX20 -> 418.91864 | CM20: =Beams!$B$12*Q20/AX20 -> 221.25984 | CN20: =SQRT( (CG20 + CH20 + CI20)^2 + 3 * ( CJ20^2 + CL20^2 ) ) -> 1688.8302 | CO20: =SQRT( (CG20 + CH20 + CI20)^2 + 3 * ( CK20^2 + CM20^2 ) ) -> 864.12425 | CQ20: =MIN(Beams!$B$21:$B$22)/MAX(CN20:CP20)-1 -> 10.842517
A21: W | B21: W40X215 | C21: W40X215 | D21: F | E21: 215 | F21: 63.5 | G21: 39 | H21: 39 | I21: – | J21: – | K21: – | L21: 15.8 | M21: 15.75 | N21: – | O21: – | P21: – | Q21: 0.65 | R21: 0.625 | S21: 0.3125 | T21: 1.22 | U21: 1.25 | V21: – | W21: – | X21: – | Y21: 2.4 | Z21: 2.5 | AA21: 1.5625 | AB21: – | AC21: – | AD21: – | AE21: – | AF21: – | AG21: 6.45 | AH21: – | AI21: – | AJ21: 52.6 | AK21: – | AL21: – | AM21: 16700 | AN21: 964 | AO21: 859 | AP21: 16.2 | AQ21: 803 | AR21: 156 | AS21: 101 | AT21: 3.54 | AU21: – | AV21: – | AW21: – | AX21: 24.8 | AY21: 284000 | AZ21: – | BA21: 149 | BB21: 719 | BC21: – | BD21: – | BE21: 175 | BF21: 473 | BG21: – | BH21: – | BI21: – | BJ21: – | BK21: – | BL21: – | BM21: – | BN21: – | BO21: – | BP21: – | BQ21: – | BR21: – | BS21: – | BT21: – | BU21: – | BV21: – | BW21: 4.19 | BX21: 37.8 | BY21: 122 | BZ21: – | CA21: 138 | CB21: 93.8 | CC21: 110 | CD21: 34 | CE21: 7.5 | CF21: 3 | CG21: =Beams!$B$11/F21 -> 177.00787 | CH21: =Beams!$B$9/AO21 -> 13.084983 | CI21: =Beams!$C$9/AS21 -> 111.28713 | CJ21: =Beams!$B$8*BE21/(AQ21*2*T21) -> 1003.9197 | CK21: =Beams!$C$8*BF21/(AM21*Q21) -> 489.77614 | CL21: =Beams!$B$12*T21/AX21 -> 552.93548 | CM21: =Beams!$B$12*Q21/AX21 -> 294.59677 | CN21: =SQRT( (CG21 + CH21 + CI21)^2 + 3 * ( CJ21^2 + CL21^2 ) ) -> 2007.8863 | CO21: =SQRT( (CG21 + CH21 + CI21)^2 + 3 * ( CK21^2 + CM21^2 ) ) -> 1034.8109 | CQ21: =MIN(Beams!$B$21:$B$22)/MAX(CN21:CP21)-1 -> 8.9607235
A22: W | B22: W40X199 | C22: W40X199 | D22: F | E22: 199 | F22: 58.8 | G22: 38.7 | H22: 38.625 | I22: – | J22: – | K22: – | L22: 15.8 | M22: 15.75 | N22: – | O22: – | P22: – | Q22: 0.65 | R22: 0.625 | S22: 0.3125 | T22: 1.07 | U22: 1.0625 | V22: – | W22: – | X22: – | Y22: 2.25 | Z22: 2.3125 | AA22: 1.5625 | AB22: – | AC22: – | AD22: – | AE22: – | AF22: – | AG22: 7.39 | AH22: – | AI22: – | AJ22: 52.6 | AK22: – | AL22: – | AM22: 14900 | AN22: 869 | AO22: 770 | AP22: 16 | AQ22: 695 | AR22: 137 | AS22: 88.2 | AT22: 3.45 | AU22: – | AV22: – | AW22: – | AX22: 18.3 | AY22: 246000 | AZ22: – | BA22: 149 | BB22: 628 | BC22: – | BD22: – | BE22: 153 | BF22: 427 | BG22: – | BH22: – | BI22: – | BJ22: – | BK22: – | BL22: – | BM22: – | BN22: – | BO22: – | BP22: – | BQ22: – | BR22: – | BS22: – | BT22: – | BU22: – | BV22: – | BW22: 4.12 | BX22: 37.6 | BY22: 121 | BZ22: – | CA22: 137 | CB22: 93.2 | CC22: 109 | CD22: 34 | CE22: 7.5 | CF22: 3 | CG22: =Beams!$B$11/F22 -> 191.15646 | CH22: =Beams!$B$9/AO22 -> 14.597403 | CI22: =Beams!$C$9/AS22 -> 127.43764 | CJ22: =Beams!$B$8*BE22/(AQ22*2*T22) -> 1156.2698 | CK22: =Beams!$C$8*BF22/(AM22*Q22) -> 495.55808 | CL22: =Beams!$B$12*T22/AX22 -> 657.20219 | CM22: =Beams!$B$12*Q22/AX22 -> 399.23497 | CN22: =SQRT( (CG22 + CH22 + CI22)^2 + 3 * ( CJ22^2 + CL22^2 ) ) -> 2327.5824 | CO22: =SQRT( (CG22 + CH22 + CI22)^2 + 3 * ( CK22^2 + CM22^2 ) ) -> 1151.4841 | CQ22: =MIN(Beams!$B$21:$B$22)/MAX(CN22:CP22)-1 -> 7.5926066
A23: W | B23: W40X392 | C23: W40X392 | D23: T | E23: 392 | F23: 116 | G23: 41.6 | H23: 41.625 | I23: – | J23: – | K23: – | L23: 12.4 | M23: 12.375 | N23: – | O23: – | P23: – | Q23: 1.42 | R23: 1.4375 | S23: 0.75 | T23: 2.52 | U23: 2.5 | V23: – | W23: – | X23: – | Y23: 3.7 | Z23: 3.8125 | AA23: 1.9375 | AB23: – | AC23: – | AD23: – | AE23: – | AF23: – | AG23: 2.45 | AH23: – | AI23: – | AJ23: 24.1 | AK23: – | AL23: – | AM23: 29900 | AN23: 1710 | AO23: 1440 | AP23: 16.1 | AQ23: 803 | AR23: 212 | AS23: 130 | AT23: 2.64 | AU23: – | AV23: – | AW23: – | AX23: 172 | AY23: 306000 | AZ23: – | BA23: 121 | BB23: 946 | BC23: – | BD23: – | BE23: 270 | BF23: 848 | BG23: – | BH23: – | BI23: – | BJ23: – | BK23: – | BL23: – | BM23: – | BN23: – | BO23: – | BP23: – | BQ23: – | BR23: – | BS23: – | BT23: – | BU23: – | BV23: – | BW23: 3.3 | BX23: 39.1 | BY23: 116 | BZ23: – | CA23: 128 | CB23: 95.6 | CC23: 108 | CD23: 34 | CE23: 7.5 | CF23: – | CG23: =Beams!$B$11/F23 -> 96.896552 | CH23: =Beams!$B$9/AO23 -> 7.8055556 | CI23: =Beams!$C$9/AS23 -> 86.461538 | CJ23: =Beams!$B$8*BE23/(AQ23*2*T23) -> 749.86657 | CK23: =Beams!$C$8*BF23/(AM23*Q23) -> 224.49291 | CL23: =Beams!$B$12*T23/AX23 -> 164.67907 | CM23: =Beams!$B$12*Q23/AX23 -> 92.795349 | CN23: =SQRT( (CG23 + CH23 + CI23)^2 + 3 * ( CJ23^2 + CL23^2 ) ) -> 1343.4287 | CO23: =SQRT( (CG23 + CH23 + CI23)^2 + 3 * ( CK23^2 + CM23^2 ) ) -> 462.13382 | CQ23: =MIN(Beams!$B$21:$B$22)/MAX(CN23:CP23)-1 -> 13.88728
A24: W | B24: W40X331 | C24: W40X331 | D24: T | E24: 331 | F24: 97.7 | G24: 40.8 | H24: 40.75 | I24: – | J24: – | K24: – | L24: 12.2 | M24: 12.125 | N24: – | O24: – | P24: – | Q24: 1.22 | R24: 1.25 | S24: 0.625 | T24: 2.13 | U24: 2.125 | V24: – | W24: – | X24: – | Y24: 3.31 | Z24: 3.375 | AA24: 1.8125 | AB24: – | AC24: – | AD24: – | AE24: – | AF24: – | AG24: 2.86 | AH24: – | AI24: – | AJ24: 28 | AK24: – | AL24: – | AM24: 24700 | AN24: 1430 | AO24: 1210 | AP24: 15.9 | AQ24: 644 | AR24: 172 | AS24: 106 | AT24: 2.57 | AU24: – | AV24: – | AW24: – | AX24: 105 | AY24: 241000 | AZ24: – | BA24: 118 | BB24: 766 | BC24: – | BD24: – | BE24: 226 | BF24: 706 | BG24: – | BH24: – | BI24: – | BJ24: – | BK24: – | BL24: – | BM24: – | BN24: – | BO24: – | BP24: – | BQ24: – | BR24: – | BS24: – | BT24: – | BU24: – | BV24: – | BW24: 3.21 | BX24: 38.7 | BY24: 114 | BZ24: – | CA24: 126 | CB24: 93.8 | CC24: 106 | CD24: 34 | CE24: 7.5 | CF24: – | CG24: =Beams!$B$11/F24 -> 115.04606 | CH24: =Beams!$B$9/AO24 -> 9.2892562 | CI24: =Beams!$C$9/AS24 -> 106.03774 | CJ24: =Beams!$B$8*BE24/(AQ24*2*T24) -> 925.93241 | CK24: =Beams!$C$8*BF24/(AM24*Q24) -> 263.33842 | CL24: =Beams!$B$12*T24/AX24 -> 228.01143 | CM24: =Beams!$B$12*Q24/AX24 -> 130.5981 | CN24: =SQRT( (CG24 + CH24 + CI24)^2 + 3 * ( CJ24^2 + CL24^2 ) ) -> 1667.6606 | CO24: =SQRT( (CG24 + CH24 + CI24)^2 + 3 * ( CK24^2 + CM24^2 ) ) -> 558.82082 | CQ24: =MIN(Beams!$B$21:$B$22)/MAX(CN24:CP24)-1 -> 10.992848
A25: W | B25: W40X327 | C25: W40X327 | D25: T | E25: 327 | F25: 95.9 | G25: 40.8 | H25: 40.75 | I25: – | J25: – | K25: – | L25: 12.1 | M25: 12.125 | N25: – | O25: – | P25: – | Q25: 1.18 | R25: 1.1875 | S25: 0.625 | T25: 2.13 | U25: 2.125 | V25: – | W25: – | X25: – | Y25: 3.31 | Z25: 3.375 | AA25: 1.8125 | AB25: – | AC25: – | AD25: – | AE25: – | AF25: – | AG25: 2.85 | AH25: – | AI25: – | AJ25: 29 | AK25: – | AL25: – | AM25: 24500 | AN25: 1410 | AO25: 1200 | AP25: 16 | AQ25: 640 | AR25: 170 | AS25: 105 | AT25: 2.58 | AU25: – | AV25: – | AW25: – | AX25: 103 | AY25: 239000 | AZ25: – | BA25: 117 | BB25: 754 | BC25: – | BD25: – | BE25: 225 | BF25: 695 | BG25: – | BH25: – | BI25: – | BJ25: – | BK25: – | BL25: – | BM25: – | BN25: – | BO25: – | BP25: – | BQ25: – | BR25: – | BS25: – | BT25: – | BU25: – | BV25: – | BW25: 3.21 | BX25: 38.7 | BY25: 114 | BZ25: – | CA25: 126 | CB25: 93.7 | CC25: 106 | CD25: 34 | CE25: 7.5 | CF25: – | CG25: =Beams!$B$11/F25 -> 117.20542 | CH25: =Beams!$B$9/AO25 -> 9.3666667 | CI25: =Beams!$C$9/AS25 -> 107.04762 | CJ25: =Beams!$B$8*BE25/(AQ25*2*T25) -> 927.59683 | CK25: =Beams!$C$8*BF25/(AM25*Q25) -> 270.211 | CL25: =Beams!$B$12*T25/AX25 -> 232.43883 | CM25: =Beams!$B$12*Q25/AX25 -> 128.76893 | CN25: =SQRT( (CG25 + CH25 + CI25)^2 + 3 * ( CJ25^2 + CL25^2 ) ) -> 1672.7131 | CO25: =SQRT( (CG25 + CH25 + CI25)^2 + 3 * ( CK25^2 + CM25^2 ) ) -> 568.65142 | CQ25: =MIN(Beams!$B$21:$B$22)/MAX(CN25:CP25)-1 -> 10.956623
A26: W | B26: W40X294 | C26: W40X294 | D26: F | E26: 294 | F26: 86.2 | G26: 40.4 | H26: 40.375 | I26: – | J26: – | K26: – | L26: 12 | M26: 12 | N26: – | O26: – | P26: – | Q26: 1.06 | R26: 1.0625 | S26: 0.5625 | T26: 1.93 | U26: 1.9375 | V26: – | W26: – | X26: – | Y26: 3.11 | Z26: 3.1875 | AA26: 1.75 | AB26: – | AC26: – | AD26: – | AE26: – | AF26: – | AG26: 3.11 | AH26: – | AI26: – | AJ26: 32.2 | AK26: – | AL26: – | AM26: 21900 | AN26: 1270 | AO26: 1080 | AP26: 15.9 | AQ26: 562 | AR26: 150 | AS26: 93.5 | AT26: 2.55 | AU26: – | AV26: – | AW26: – | AX26: 76.6 | AY26: 208000 | AZ26: – | BA26: 115 | BB26: 668 | BC26: – | BD26: – | BE26: 203 | BF26: 622 | BG26: – | BH26: – | BI26: – | BJ26: – | BK26: – | BL26: – | BM26: – | BN26: – | BO26: – | BP26: – | BQ26: – | BR26: – | BS26: – | BT26: – | BU26: – | BV26: – | BW26: 3.16 | BX26: 38.5 | BY26: 113 | BZ26: – | CA26: 125 | CB26: 92.8 | CC26: 105 | CD26: 34 | CE26: 7.5 | CF26: – | CG26: =Beams!$B$11/F26 -> 130.39443 | CH26: =Beams!$B$9/AO26 -> 10.407407 | CI26: =Beams!$C$9/AS26 -> 120.2139 | CJ26: =Beams!$B$8*BE26/(AQ26*2*T26) -> 1051.8135 | CK26: =Beams!$C$8*BF26/(AM26*Q26) -> 301.16654 | CL26: =Beams!$B$12*T26/AX26 -> 283.20104 | CM26: =Beams!$B$12*Q26/AX26 -> 155.54047 | CN26: =SQRT( (CG26 + CH26 + CI26)^2 + 3 * ( CJ26^2 + CL26^2 ) ) -> 1904.645 | CO26: =SQRT( (CG26 + CH26 + CI26)^2 + 3 * ( CK26^2 + CM26^2 ) ) -> 642.50415 | CQ26: =MIN(Beams!$B$21:$B$22)/MAX(CN26:CP26)-1 -> 9.5006447
A27: W | B27: W40X278 | C27: W40X278 | D27: F | E27: 278 | F27: 82.3 | G27: 40.2 | H27: 40.125 | I27: – | J27: – | K27: – | L27: 12 | M27: 12 | N27: – | O27: – | P27: – | Q27: 1.03 | R27: 1 | S27: 0.5 | T27: 1.81 | U27: 1.8125 | V27: – | W27: – | X27: – | Y27: 2.99 | Z27: 3.0625 | AA27: 1.75 | AB27: – | AC27: – | AD27: – | AE27: – | AF27: – | AG27: 3.31 | AH27: – | AI27: – | AJ27: 33.3 | AK27: – | AL27: – | AM27: 20500 | AN27: 1190 | AO27: 1020 | AP27: 15.8 | AQ27: 521 | AR27: 140 | AS27: 87.1 | AT27: 2.52 | AU27: – | AV27: – | AW27: – | AX27: 65 | AY27: 192000 | AZ27: – | BA27: 115 | BB27: 622 | BC27: – | BD27: – | BE27: 190 | BF27: 587 | BG27: – | BH27: – | BI27: – | BJ27: – | BK27: – | BL27: – | BM27: – | BN27: – | BO27: – | BP27: – | BQ27: – | BR27: – | BS27: – | BT27: – | BU27: – | BV27: – | BW27: 3.13 | BX27: 38.4 | BY27: 112 | BZ27: – | CA27: 124 | CB27: 92.4 | CC27: 104 | CD27: 34 | CE27: 7.5 | CF27: – | CG27: =Beams!$B$11/F27 -> 136.57351 | CH27: =Beams!$B$9/AO27 -> 11.019608 | CI27: =Beams!$C$9/AS27 -> 129.04707 | CJ27: =Beams!$B$8*BE27/(AQ27*2*T27) -> 1132.3316 | CK27: =Beams!$C$8*BF27/(AM27*Q27) -> 312.4736 | CL27: =Beams!$B$12*T27/AX27 -> 312.99077 | CM27: =Beams!$B$12*Q27/AX27 -> 178.11077 | CN27: =SQRT( (CG27 + CH27 + CI27)^2 + 3 * ( CJ27^2 + CL27^2 ) ) -> 2053.5199 | CO27: =SQRT( (CG27 + CH27 + CI27)^2 + 3 * ( CK27^2 + CM27^2 ) ) -> 681.62994 | CQ27: =MIN(Beams!$B$21:$B$22)/MAX(CN27:CP27)-1 -> 8.739375
A28: W | B28: W40X264 | C28: W40X264 | D28: F | E28: 264 | F28: 77.4 | G28: 40 | H28: 40 | I28: – | J28: – | K28: – | L28: 11.9 | M28: 11.875 | N28: – | O28: – | P28: – | Q28: 0.96 | R28: 0.9375 | S28: 0.5 | T28: 1.73 | U28: 1.75 | V28: – | W28: – | X28: – | Y28: 2.91 | Z28: 3 | AA28: 1.6875 | AB28: – | AC28: – | AD28: – | AE28: – | AF28: – | AG28: 3.45 | AH28: – | AI28: – | AJ28: 35.6 | AK28: – | AL28: – | AM28: 19400 | AN28: 1130 | AO28: 971 | AP28: 15.8 | AQ28: 493 | AR28: 132 | AS28: 82.6 | AT28: 2.52 | AU28: – | AV28: – | AW28: – | AX28: 56.1 | AY28: 181000 | AZ28: – | BA28: 114 | BB28: 589 | BC28: – | BD28: – | BE28: 182 | BF28: 555 | BG28: – | BH28: – | BI28: – | BJ28: – | BK28: – | BL28: – | BM28: – | BN28: – | BO28: – | BP28: – | BQ28: – | BR28: – | BS28: – | BT28: – | BU28: – | BV28: – | BW28: 3.12 | BX28: 38.3 | BY28: 112 | BZ28: – | CA28: 124 | CB28: 91.9 | CC28: 104 | CD28: 34 | CE28: 7.5 | CF28: – | CG28: =Beams!$B$11/F28 -> 145.21964 | CH28: =Beams!$B$9/AO28 -> 11.575695 | CI28: =Beams!$C$9/AS28 -> 136.07748 | CJ28: =Beams!$B$8*BE28/(AQ28*2*T28) -> 1199.2637 | CK28: =Beams!$C$8*BF28/(AM28*Q28) -> 334.9549 | CL28: =Beams!$B$12*T28/AX28 -> 346.61676 | CM28: =Beams!$B$12*Q28/AX28 -> 192.34225 | CN28: =SQRT( (CG28 + CH28 + CI28)^2 + 3 * ( CJ28^2 + CL28^2 ) ) -> 2181.9496 | CO28: =SQRT( (CG28 + CH28 + CI28)^2 + 3 * ( CK28^2 + CM28^2 ) ) -> 730.30504 | CQ28: =MIN(Beams!$B$21:$B$22)/MAX(CN28:CP28)-1 -> 8.1661145
A29: W | B29: W40X235 | C29: W40X235 | D29: F | E29: 235 | F29: 69.1 | G29: 39.7 | H29: 39.75 | I29: – | J29: – | K29: – | L29: 11.9 | M29: 11.875 | N29: – | O29: – | P29: – | Q29: 0.83 | R29: 0.8125 | S29: 0.4375 | T29: 1.58 | U29: 1.5625 | V29: – | W29: – | X29: – | Y29: 2.76 | Z29: 2.875 | AA29: 1.625 | AB29: – | AC29: – | AD29: – | AE29: – | AF29: – | AG29: 3.77 | AH29: – | AI29: – | AJ29: 41.2 | AK29: – | AL29: – | AM29: 17400 | AN29: 1010 | AO29: 875 | AP29: 15.9 | AQ29: 444 | AR29: 118 | AS29: 74.6 | AT29: 2.54 | AU29: – | AV29: – | AW29: – | AX29: 41.3 | AY29: 161000 | AZ29: – | BA29: 113 | BB29: 530 | BC29: – | BD29: – | BE29: 166 | BF29: 495 | BG29: – | BH29: – | BI29: – | BJ29: – | BK29: – | BL29: – | BM29: – | BN29: – | BO29: – | BP29: – | BQ29: – | BR29: – | BS29: – | BT29: – | BU29: – | BV29: – | BW29: 3.11 | BX29: 38.1 | BY29: 111 | BZ29: – | CA29: 123 | CB29: 91.3 | CC29: 103 | CD29: 34 | CE29: 7.5 | CF29: – | CG29: =Beams!$B$11/F29 -> 162.66281 | CH29: =Beams!$B$9/AO29 -> 12.845714 | CI29: =Beams!$C$9/AS29 -> 150.67024 | CJ29: =Beams!$B$8*BE29/(AQ29*2*T29) -> 1329.8552 | CK29: =Beams!$C$8*BF29/(AM29*Q29) -> 385.25135 | CL29: =Beams!$B$12*T29/AX29 -> 430.00484 | CM29: =Beams!$B$12*Q29/AX29 -> 225.88862 | CN29: =SQRT( (CG29 + CH29 + CI29)^2 + 3 * ( CJ29^2 + CL29^2 ) ) -> 2442.6726 | CO29: =SQRT( (CG29 + CH29 + CI29)^2 + 3 * ( CK29^2 + CM29^2 ) ) -> 839.47924 | CQ29: =MIN(Beams!$B$21:$B$22)/MAX(CN29:CP29)-1 -> 7.1877531
A30: W | B30: W40X211 | C30: W40X211 | D30: F | E30: 211 | F30: 62.1 | G30: 39.4 | H30: 39.375 | I30: – | J30: – | K30: – | L30: 11.8 | M30: 11.75 | N30: – | O30: – | P30: – | Q30: 0.75 | R30: 0.75 | S30: 0.375 | T30: 1.42 | U30: 1.4375 | V30: – | W30: – | X30: – | Y30: 2.6 | Z30: 2.6875 | AA30: 1.5625 | AB30: – | AC30: – | AD30: – | AE30: – | AF30: – | AG30: 4.17 | AH30: – | AI30: – | AJ30: 45.6 | AK30: – | AL30: – | AM30: 15500 | AN30: 906 | AO30: 786 | AP30: 15.8 | AQ30: 390 | AR30: 105 | AS30: 66.1 | AT30: 2.51 | AU30: – | AV30: – | AW30: – | AX30: 30.4 | AY30: 141000 | AZ30: – | BA30: 112 | BB30: 468 | BC30: – | BD30: – | BE30: 148 | BF30: 442 | BG30: – | BH30: – | BI30: – | BJ30: – | BK30: – | BL30: – | BM30: – | BN30: – | BO30: – | BP30: – | BQ30: – | BR30: – | BS30: – | BT30: – | BU30: – | BV30: – | BW30: 3.07 | BX30: 38 | BY30: 110 | BZ30: – | CA30: 122 | CB30: 90.6 | CC30: 102 | CD30: 34 | CE30: 7.5 | CF30: – | CG30: =Beams!$B$11/F30 -> 180.99839 | CH30: =Beams!$B$9/AO30 -> 14.300254 | CI30: =Beams!$C$9/AS30 -> 170.04539 | CJ30: =Beams!$B$8*BE30/(AQ30*2*T30) -> 1501.914 | CK30: =Beams!$C$8*BF30/(AM30*Q30) -> 427.36172 | CL30: =Beams!$B$12*T30/AX30 -> 525.02632 | CM30: =Beams!$B$12*Q30/AX30 -> 277.30263 | CN30: =SQRT( (CG30 + CH30 + CI30)^2 + 3 * ( CJ30^2 + CL30^2 ) ) -> 2779.869 | CO30: =SQRT( (CG30 + CH30 + CI30)^2 + 3 * ( CK30^2 + CM30^2 ) ) -> 955.02912 | CQ30: =MIN(Beams!$B$21:$B$22)/MAX(CN30:CP30)-1 -> 6.1945837
A31: W | B31: W40X183 | C31: W40X183 | D31: F | E31: 183 | F31: 53.3 | G31: 39 | H31: 39 | I31: – | J31: – | K31: – | L31: 11.8 | M31: 11.75 | N31: – | O31: – | P31: – | Q31: 0.65 | R31: 0.625 | S31: 0.3125 | T31: 1.2 | U31: 1.1875 | V31: – | W31: – | X31: – | Y31: 2.38 | Z31: 2.5 | AA31: 1.5625 | AB31: – | AC31: – | AD31: – | AE31: – | AF31: – | AG31: 4.92 | AH31: – | AI31: – | AJ31: 52.6 | AK31: – | AL31: – | AM31: 13200 | AN31: 774 | AO31: 675 | AP31: 15.7 | AQ31: 331 | AR31: 88.3 | AS31: 56 | AT31: 2.49 | AU31: – | AV31: – | AW31: – | AX31: 19.3 | AY31: 118000 | AZ31: – | BA31: 112 | BB31: 395 | BC31: – | BD31: – | BE31: 126 | BF31: 376 | BG31: – | BH31: – | BI31: – | BJ31: – | BK31: – | BL31: – | BM31: – | BN31: – | BO31: – | BP31: – | BQ31: – | BR31: – | BS31: – | BT31: – | BU31: – | BV31: – | BW31: 3.04 | BX31: 37.8 | BY31: 110 | BZ31: – | CA31: 122 | CB31: 89.8 | CC31: 102 | CD31: 34 | CE31: 7.5 | CF31: – | CG31: =Beams!$B$11/F31 -> 210.8818 | CH31: =Beams!$B$9/AO31 -> 16.651852 | CI31: =Beams!$C$9/AS31 -> 200.71429 | CJ31: =Beams!$B$8*BE31/(AQ31*2*T31) -> 1782.7795 | CK31: =Beams!$C$8*BF31/(AM31*Q31) -> 492.56876 | CL31: =Beams!$B$12*T31/AX31 -> 698.8601 | CM31: =Beams!$B$12*Q31/AX31 -> 378.54922 | CN31: =SQRT( (CG31 + CH31 + CI31)^2 + 3 * ( CJ31^2 + CL31^2 ) ) -> 3344.1771 | CO31: =SQRT( (CG31 + CH31 + CI31)^2 + 3 * ( CK31^2 + CM31^2 ) ) -> 1158.0876 | CQ31: =MIN(Beams!$B$21:$B$22)/MAX(CN31:CP31)-1 -> 4.9805445
A32: W | B32: W40X167 | C32: W40X167 | D32: F | E32: 167 | F32: 49.3 | G32: 38.6 | H32: 38.625 | I32: – | J32: – | K32: – | L32: 11.8 | M32: 11.75 | N32: – | O32: – | P32: – | Q32: 0.65 | R32: 0.625 | S32: 0.3125 | T32: 1.03 | U32: 1 | V32: – | W32: – | X32: – | Y32: 2.21 | Z32: 2.3125 | AA32: 1.5625 | AB32: – | AC32: – | AD32: – | AE32: – | AF32: – | AG32: 5.76 | AH32: – | AI32: – | AJ32: 52.6 | AK32: – | AL32: – | AM32: 11600 | AN32: 693 | AO32: 600 | AP32: 15.3 | AQ32: 283 | AR32: 76 | AS32: 47.9 | AT32: 2.4 | AU32: – | AV32: – | AW32: – | AX32: 14 | AY32: 99700 | AZ32: – | BA32: 111 | BB32: 336 | BC32: – | BD32: – | BE32: 107 | BF32: 336 | BG32: – | BH32: – | BI32: – | BJ32: – | BK32: – | BL32: – | BM32: – | BN32: – | BO32: – | BP32: – | BQ32: – | BR32: – | BS32: – | BT32: – | BU32: – | BV32: – | BW32: 2.98 | BX32: 37.6 | BY32: 109 | BZ32: – | CA32: 121 | CB32: 89 | CC32: 101 | CD32: 34 | CE32: 7.5 | CF32: – | CG32: =Beams!$B$11/F32 -> 227.99189 | CH32: =Beams!$B$9/AO32 -> 18.733333 | CI32: =Beams!$C$9/AS32 -> 234.65553 | CJ32: =Beams!$B$8*BE32/(AQ32*2*T32) -> 2062.9867 | CK32: =Beams!$C$8*BF32/(AM32*Q32) -> 500.88064 | CL32: =Beams!$B$12*T32/AX32 -> 826.94286 | CM32: =Beams!$B$12*Q32/AX32 -> 521.85714 | CN32: =SQRT( (CG32 + CH32 + CI32)^2 + 3 * ( CJ32^2 + CL32^2 ) ) -> 3879.5584 | CO32: =SQRT( (CG32 + CH32 + CI32)^2 + 3 * ( CK32^2 + CM32^2 ) ) -> 1342.1536 | CQ32: =MIN(Beams!$B$21:$B$22)/MAX(CN32:CP32)-1 -> 4.1552259
A33: W | B33: W40X149 | C33: W40X149 | D33: F | E33: 149 | F33: 43.8 | G33: 38.2 | H33: 38.25 | I33: – | J33: – | K33: – | L33: 11.8 | M33: 11.75 | N33: – | O33: – | P33: – | Q33: 0.63 | R33: 0.625 | S33: 0.3125 | T33: 0.83 | U33: 0.8125 | V33: – | W33: – | X33: – | Y33: 2.01 | Z33: 2.125 | AA33: 1.5 | AB33: – | AC33: – | AD33: – | AE33: – | AF33: – | AG33: 7.11 | AH33: – | AI33: – | AJ33: 54.3 | AK33: – | AL33: – | AM33: 9800 | AN33: 598 | AO33: 513 | AP33: 15 | AQ33: 229 | AR33: 62.2 | AS33: 38.8 | AT33: 2.29 | AU33: – | AV33: – | AW33: – | AX33: 9.36 | AY33: 80000 | AZ33: – | BA33: 110 | BB33: 270 | BC33: – | BD33: – | BE33: 86.7 | BF33: 288 | BG33: – | BH33: – | BI33: – | BJ33: – | BK33: – | BL33: – | BM33: – | BN33: – | BO33: – | BP33: – | BQ33: – | BR33: – | BS33: – | BT33: – | BU33: – | BV33: – | BW33: 2.89 | BX33: 37.4 | BY33: 108 | BZ33: – | CA33: 120 | CB33: 88.2 | CC33: 100 | CD33: 34 | CE33: 7.5 | CF33: – | CG33: =Beams!$B$11/F33 -> 256.621 | CH33: =Beams!$B$9/AO33 -> 21.910331 | CI33: =Beams!$C$9/AS33 -> 289.69072 | CJ33: =Beams!$B$8*BE33/(AQ33*2*T33) -> 2563.5503 | CK33: =Beams!$C$8*BF33/(AM33*Q33) -> 524.31487 | CL33: =Beams!$B$12*T33/AX33 -> 996.7094 | CM33: =Beams!$B$12*Q33/AX33 -> 756.53846 | CN33: =SQRT( (CG33 + CH33 + CI33)^2 + 3 * ( CJ33^2 + CL33^2 ) ) -> 4797.7636 | CO33: =SQRT( (CG33 + CH33 + CI33)^2 + 3 * ( CK33^2 + CM33^2 ) ) -> 1692.5265 | CQ33: =MIN(Beams!$B$21:$B$22)/MAX(CN33:CP33)-1 -> 3.1686089
A34: W | B34: W36X925 | C34: W36X925 | D34: T | E34: 925 | F34: 272 | G34: 43.1 | H34: 43.125 | I34: – | J34: – | K34: – | L34: 18.6 | M34: 18.625 | N34: – | O34: – | P34: – | Q34: 3.02 | R34: 3 | S34: 1.5 | T34: 4.53 | U34: 4.5 | V34: – | W34: – | X34: – | Y34: 5.28 | Z34: 5.375 | AA34: 2.3125 | AB34: – | AC34: – | AD34: – | AE34: – | AF34: – | AG34: 2.05 | AH34: – | AI34: – | AJ34: 10.8 | AK34: – | AL34: – | AM34: 73000 | AN34: 4130 | AO34: 3390 | AP34: 16.4 | AQ34: 4940 | AR34: 862 | AS34: 531 | AT34: 4.26 | AU34: – | AV34: – | AW34: – | AX34: 1430 | AY34: 1840000 | AZ34: – | BA34: 179 | BB34: 3780 | BC34: – | BD34: – | BE34: 681 | BF34: 2060 | BG34: – | BH34: – | BI34: – | BJ34: – | BK34: – | BL34: – | BM34: – | BN34: – | BO34: – | BP34: – | BQ34: – | BR34: – | BS34: – | BT34: – | BU34: – | BV34: – | BW34: 5.3 | BX34: 38.6 | BY34: 134 | BZ34: – | CA34: 153 | CB34: 105 | CC34: 124 | CD34: 32.375 | CE34: 7.5 | CF34: 3 | CG34: =Beams!$B$11/F34 -> 41.323529 | CH34: =Beams!$B$9/AO34 -> 3.3156342 | CI34: =Beams!$C$9/AS34 -> 21.167608 | CJ34: =Beams!$B$8*BE34/(AQ34*2*T34) -> 171.02448 | CK34: =Beams!$C$8*BF34/(AM34*Q34) -> 105.02767 | CL34: =Beams!$B$12*T34/AX34 -> 35.606434 | CM34: =Beams!$B$12*Q34/AX34 -> 23.737622 | CN34: =SQRT( (CG34 + CH34 + CI34)^2 + 3 * ( CJ34^2 + CL34^2 ) ) -> 309.64835 | CO34: =SQRT( (CG34 + CH34 + CI34)^2 + 3 * ( CK34^2 + CM34^2 ) ) -> 197.77105 | CQ34: =MIN(Beams!$B$21:$B$22)/MAX(CN34:CP34)-1 -> 63.589396
A35: W | B35: W36X853 | C35: W36X853 | D35: T | E35: 853 | F35: 251 | G35: 43.1 | H35: 43.125 | I35: – | J35: – | K35: – | L35: 18.2 | M35: 18.25 | N35: – | O35: – | P35: – | Q35: 2.52 | R35: 2.5 | S35: 1.25 | T35: 4.53 | U35: 4.5 | V35: – | W35: – | X35: – | Y35: 5.28 | Z35: 5.375 | AA35: 2.0625 | AB35: – | AC35: – | AD35: – | AE35: – | AF35: – | AG35: 2.01 | AH35: – | AI35: – | AJ35: 12.9 | AK35: – | AL35: – | AM35: 70000 | AN35: 3920 | AO35: 3250 | AP35: 16.7 | AQ35: 4600 | AR35: 805 | AS35: 505 | AT35: 4.28 | AU35: – | AV35: – | AW35: – | AX35: 1240 | AY35: 1710000 | AZ35: – | BA35: 175 | BB35: 3620 | BC35: – | BD35: – | BE35: 685 | BF35: 1950 | BG35: – | BH35: – | BI35: – | BJ35: – | BK35: – | BL35: – | BM35: – | BN35: – | BO35: – | BP35: – | BQ35: – | BR35: – | BS35: – | BT35: – | BU35: – | BV35: – | BW35: 5.22 | BX35: 38.6 | BY35: 135 | BZ35: – | CA35: 153 | CB35: 104 | CC35: 122 | CD35: 32.375 | CE35: 7.5 | CF35: 3 | CG35: =Beams!$B$11/F35 -> 44.780876 | CH35: =Beams!$B$9/AO35 -> 3.4584615 | CI35: =Beams!$C$9/AS35 -> 22.257426 | CJ35: =Beams!$B$8*BE35/(AQ35*2*T35) -> 184.74422 | CK35: =Beams!$C$8*BF35/(AM35*Q35) -> 124.2517 | CL35: =Beams!$B$12*T35/AX35 -> 41.062258 | CM35: =Beams!$B$12*Q35/AX35 -> 22.842581 | CN35: =SQRT( (CG35 + CH35 + CI35)^2 + 3 * ( CJ35^2 + CL35^2 ) ) -> 335.29002 | CO35: =SQRT( (CG35 + CH35 + CI35)^2 + 3 * ( CK35^2 + CM35^2 ) ) -> 229.89258 | CQ35: =MIN(Beams!$B$21:$B$22)/MAX(CN35:CP35)-1 -> 58.649852
